Workbook

Sheet README
B2: Loss Ratio Model - Canadian Commercial Property
B3: Industry-level, net of reinsurance, $ millions CAD, calendar years 2010-2022
B5: Purpose | C5: Calculate and track the calendar-year loss ratio for the Canadian commercial property line, and provide a single-book calculator for your own portfolio.
B6: Line of business | C6: Commercial property (private P&C insurers; excludes government-run insurers).
B7: Data source | C7: Source: Insurance Bureau of Canada (IBC), Facts of the Property and Casualty Insurance Industry in Canada 2023, Section 1, pp. 9 & 11 (data: IBC, MSA Research, SCOR, AMF). https://ibc.ca/industry-resources/resources-data/facts-book
B8: Core formula | C8: Loss Ratio = Incurred Losses (incl. LAE load) / Earned Premium
B9: Earned premium | C9: IBC publishes written premium, not earned. Earned premium is estimated with the annual-policy, uniform-writing assumption: NEP(t) = f x NWP(t) + (1 - f) x NWP(t-1), with f = 50% by default (editable on Inputs).
B10: Incurred losses | C10: Net claims incurred as published by IBC (paid + change in case reserves + change in IBNR, net of reinsurance). An optional ULAE load can be added on Inputs.
B11: Sheets | C11: Inputs - data and assumptions | LR_Model - loss ratio by year, summary stats, charts | Line_Comparison_2022 - loss ratios across all lines | Benchmarks - check vs published ratios | Calculator - loss / LAE / combined ratio for your own book. | Triangle_Data - paid / reported / case triangles (illustrative) | Chain_Ladder - age-to-age factors, LDF selection, CDFs | Reserve_Summary - ultimates, IBNR, chain-ladder vs Bornhuetter-Ferguson.
B12: Colour legend | C12: Blue text = hardcoded input | Black = formula | Green = link from another sheet | Yellow fill = key assumption you can change.
B13: How to use | C13: 1) Change yellow assumptions on Inputs (earning fraction, ULAE load, target LR). 2) Add a new year: extend the Inputs table and copy the last LR_Model row down. 3) Use Calculator for your own premium and claims figures.
B14: Caveats | C14: IBC figures are IFRS 4 based; 2023+ data under IFRS 17 is not directly comparable. Calendar-year ratios mix current accident year and prior-year reserve development. 2010 has no prior-year NWP in the source, so its earned premium is not estimated. Loss triangles are SIMULATED for illustration; replace with company data.
B17: Legend examples:
B18: 1000 | C18: Hardcoded input
B19: =B18*2 -> 2000 | C19: Formula
B20: =Inputs!C5 -> 0.5 | C20: Link from another sheet
B21: 0.65 | C21: Key assumption (editable)

Sheet Inputs
A1: Inputs & Assumptions - Commercial Property (Canada)
A2: Edit yellow cells. Blue = hardcoded data. All $ in millions CAD.
A4: Assumptions
B5: Earning fraction of current-year NWP (f) | C5: 0.5 | E5: Annual policies written evenly through the year earn ~50% in the year written and 50% the next year.
B6: ULAE load (% of net claims incurred) | C6: 0 | E6: Optional unallocated loss adjustment expense load. 0% = use IBC net claims incurred as published.
B7: Target (permissible) loss ratio | C7: 0.65 | E7: Illustrative target. Set to your own pricing permissible loss ratio (1 - expense ratio - profit margin).
A10: Historical data - Commercial property, Canada (net of reinsurance)
A11: Year | B11: Notes | C11: Net Written Premium ($mm) | D11: Net Claims Incurred ($mm) | E11: Source
A12: 2010 | B12: No 2009 NWP in source - NEP not estimated | C12: 5568 | D12: 3276 | E12: IBC Facts Book 2023, p.9 (NWP) & p.11 (NCI)
A13: 2011 | C13: 6014 | D13: 4087 | E13: IBC Facts Book 2023, p.9 (NWP) & p.11 (NCI)
A14: 2012 | C14: 6136 | D14: 3981 | E14: IBC Facts Book 2023, p.9 (NWP) & p.11 (NCI)
A15: 2013 | C15: 6339 | D15: 4699 | E15: IBC Facts Book 2023, p.9 (NWP) & p.11 (NCI)
A16: 2014 | B16: Cross-check: IBC cites LR 62% (2012) -> 77% (2013) | C16: 6621 | D16: 3955 | E16: IBC Facts Book 2023, p.9 (NWP) & p.11 (NCI)
A17: 2015 | C17: 6656 | D17: 3797 | E17: IBC Facts Book 2023, p.9 (NWP) & p.11 (NCI)
A18: 2016 | C18: 6704 | D18: 5494 | E18: IBC Facts Book 2023, p.9 (NWP) & p.11 (NCI)
A19: 2017 | C19: 6941 | D19: 4280 | E19: IBC Facts Book 2023, p.9 (NWP) & p.11 (NCI)
A20: 2018 | C20: 7638 | D20: 5471 | E20: IBC Facts Book 2023, p.9 (NWP) & p.11 (NCI)
A21: 2019 | C21: 8111 | D21: 5015 | E21: IBC Facts Book 2023, p.9 (NWP) & p.11 (NCI)
A22: 2020 | B22: COVID-era hard market; strong premium growth | C22: 9654 | D22: 5525 | E22: IBC Facts Book 2023, p.9 (NWP) & p.11 (NCI)
A23: 2021 | C23: 10982 | D23: 4673 | E23: IBC Facts Book 2023, p.9 (NWP) & p.11 (NCI)
A24: 2022 | C24: 11892 | D24: 5716 | E24: IBC Facts Book 2023, p.9 (NWP) & p.11 (NCI)
A26: Source: Insurance Bureau of Canada (IBC), Facts of the Property and Casualty Insurance Industry in Canada 2023, Section 1, pp. 9 & 11 (data: IBC, MSA Research, SCOR, AMF). https://ibc.ca/industry-resources/resources-data/facts-book

Sheet LR_Model
A1: Loss Ratio Model - Canadian Commercial Property
A2: Calendar-year, net of reinsurance, $ millions CAD. Loss Ratio = (NCI + ULAE) / Net Earned Premium.
A3: Earning fraction f: | C3: =Inputs!C5 -> 0.5 | D3: ULAE load: | E3: =Inputs!C6 -> 0 | F3: Target LR: | G3: =Inputs!C7 -> 0.65
A5: Year | B5: NWP current yr ($mm) | C5: NWP prior yr ($mm) | D5: Net Earned Premium ($mm) | E5: Net Claims Incurred ($mm) | F5: ULAE ($mm) | G5: Total Incurred ($mm) | H5: Loss Ratio (earned) | I5: Loss Ratio (written basis) | J5: Target LR | K5: Variance vs Target | L5: Status | M5: YoY change in LR
A6: =Inputs!A13 -> 2011 | B6: =Inputs!C13 -> 6014 | C6: =Inputs!C12 -> 5568 | D6: =$C$3*B6+(1-$C$3)*C6 -> 5791 | E6: =Inputs!D13 -> 4087 | F6: =E6*$E$3 -> 0 | G6: =E6+F6 -> 4087 | H6: =IF(D6=0,0,G6/D6) -> 0.7057503 | I6: =IF(B6=0,0,G6/B6) -> 0.67958098 | J6: =$G$3 -> 0.65 | K6: =H6-J6 -> 0.055750302 | L6: =IF(H6>J6,"Above target","Within target") -> Above target
A7: =Inputs!A14 -> 2012 | B7: =Inputs!C14 -> 6136 | C7: =Inputs!C13 -> 6014 | D7: =$C$3*B7+(1-$C$3)*C7 -> 6075 | E7: =Inputs!D14 -> 3981 | F7: =E7*$E$3 -> 0 | G7: =E7+F7 -> 3981 | H7: =IF(D7=0,0,G7/D7) -> 0.65530864 | I7: =IF(B7=0,0,G7/B7) -> 0.648794 | J7: =$G$3 -> 0.65 | K7: =H7-J7 -> 0.005308642 | L7: =IF(H7>J7,"Above target","Within target") -> Above target | M7: =H7-H6 -> -0.05044166
A8: =Inputs!A15 -> 2013 | B8: =Inputs!C15 -> 6339 | C8: =Inputs!C14 -> 6136 | D8: =$C$3*B8+(1-$C$3)*C8 -> 6237.5 | E8: =Inputs!D15 -> 4699 | F8: =E8*$E$3 -> 0 | G8: =E8+F8 -> 4699 | H8: =IF(D8=0,0,G8/D8) -> 0.75334669 | I8: =IF(B8=0,0,G8/B8) -> 0.74128411 | J8: =$G$3 -> 0.65 | K8: =H8-J8 -> 0.10334669 | L8: =IF(H8>J8,"Above target","Within target") -> Above target | M8: =H8-H7 -> 0.098038051
A9: =Inputs!A16 -> 2014 | B9: =Inputs!C16 -> 6621 | C9: =Inputs!C15 -> 6339 | D9: =$C$3*B9+(1-$C$3)*C9 -> 6480 | E9: =Inputs!D16 -> 3955 | F9: =E9*$E$3 -> 0 | G9: =E9+F9 -> 3955 | H9: =IF(D9=0,0,G9/D9) -> 0.61033951 | I9: =IF(B9=0,0,G9/B9) -> 0.59734179 | J9: =$G$3 -> 0.65 | K9: =H9-J9 -> -0.039660494 | L9: =IF(H9>J9,"Above target","Within target") -> Within target | M9: =H9-H8 -> -0.14300719
A10: =Inputs!A17 -> 2015 | B10: =Inputs!C17 -> 6656 | C10: =Inputs!C16 -> 6621 | D10: =$C$3*B10+(1-$C$3)*C10 -> 6638.5 | E10: =Inputs!D17 -> 3797 | F10: =E10*$E$3 -> 0 | G10: =E10+F10 -> 3797 | H10: =IF(D10=0,0,G10/D10) -> 0.57196656 | I10: =IF(B10=0,0,G10/B10) -> 0.57046274 | J10: =$G$3 -> 0.65 | K10: =H10-J10 -> -0.078033441 | L10: =IF(H10>J10,"Above target","Within target") -> Within target | M10: =H10-H9 -> -0.038372947
A11: =Inputs!A18 -> 2016 | B11: =Inputs!C18 -> 6704 | C11: =Inputs!C17 -> 6656 | D11: =$C$3*B11+(1-$C$3)*C11 -> 6680 | E11: =Inputs!D18 -> 5494 | F11: =E11*$E$3 -> 0 | G11: =E11+F11 -> 5494 | H11: =IF(D11=0,0,G11/D11) -> 0.82245509 | I11: =IF(B11=0,0,G11/B11) -> 0.81951074 | J11: =$G$3 -> 0.65 | K11: =H11-J11 -> 0.17245509 | L11: =IF(H11>J11,"Above target","Within target") -> Above target | M11: =H11-H10 -> 0.25048853
A12: =Inputs!A19 -> 2017 | B12: =Inputs!C19 -> 6941 | C12: =Inputs!C18 -> 6704 | D12: =$C$3*B12+(1-$C$3)*C12 -> 6822.5 | E12: =Inputs!D19 -> 4280 | F12: =E12*$E$3 -> 0 | G12: =E12+F12 -> 4280 | H12: =IF(D12=0,0,G12/D12) -> 0.62733602 | I12: =IF(B12=0,0,G12/B12) -> 0.61662585 | J12: =$G$3 -> 0.65 | K12: =H12-J12 -> -0.022663979 | L12: =IF(H12>J12,"Above target","Within target") -> Within target | M12: =H12-H11 -> -0.19511907
A13: =Inputs!A20 -> 2018 | B13: =Inputs!C20 -> 7638 | C13: =Inputs!C19 -> 6941 | D13: =$C$3*B13+(1-$C$3)*C13 -> 7289.5 | E13: =Inputs!D20 -> 5471 | F13: =E13*$E$3 -> 0 | G13: =E13+F13 -> 5471 | H13: =IF(D13=0,0,G13/D13) -> 0.75053159 | I13: =IF(B13=0,0,G13/B13) -> 0.71628699 | J13: =$G$3 -> 0.65 | K13: =H13-J13 -> 0.10053159 | L13: =IF(H13>J13,"Above target","Within target") -> Above target | M13: =H13-H12 -> 0.12319557
A14: =Inputs!A21 -> 2019 | B14: =Inputs!C21 -> 8111 | C14: =Inputs!C20 -> 7638 | D14: =$C$3*B14+(1-$C$3)*C14 -> 7874.5 | E14: =Inputs!D21 -> 5015 | F14: =E14*$E$3 -> 0 | G14: =E14+F14 -> 5015 | H14: =IF(D14=0,0,G14/D14) -> 0.63686583 | I14: =IF(B14=0,0,G14/B14) -> 0.61829614 | J14: =$G$3 -> 0.65 | K14: =H14-J14 -> -0.013134167 | L14: =IF(H14>J14,"Above target","Within target") -> Within target | M14: =H14-H13 -> -0.11366575
A15: =Inputs!A22 -> 2020 | B15: =Inputs!C22 -> 9654 | C15: =Inputs!C21 -> 8111 | D15: =$C$3*B15+(1-$C$3)*C15 -> 8882.5 | E15: =Inputs!D22 -> 5525 | F15: =E15*$E$3 -> 0 | G15: =E15+F15 -> 5525 | H15: =IF(D15=0,0,G15/D15) -> 0.62200957 | I15: =IF(B15=0,0,G15/B15) -> 0.57230164 | J15: =$G$3 -> 0.65 | K15: =H15-J15 -> -0.027990431 | L15: =IF(H15>J15,"Above target","Within target") -> Within target | M15: =H15-H14 -> -0.014856263
A16: =Inputs!A23 -> 2021 | B16: =Inputs!C23 -> 10982 | C16: =Inputs!C22 -> 9654 | D16: =$C$3*B16+(1-$C$3)*C16 -> 10318 | E16: =Inputs!D23 -> 4673 | F16: =E16*$E$3 -> 0 | G16: =E16+F16 -> 4673 | H16: =IF(D16=0,0,G16/D16) -> 0.45289785 | I16: =IF(B16=0,0,G16/B16) -> 0.42551448 | J16: =$G$3 -> 0.65 | K16: =H16-J16 -> -0.19710215 | L16: =IF(H16>J16,"Above target","Within target") -> Within target | M16: =H16-H15 -> -0.16911172
A17: =Inputs!A24 -> 2022 | B17: =Inputs!C24 -> 11892 | C17: =Inputs!C23 -> 10982 | D17: =$C$3*B17+(1-$C$3)*C17 -> 11437 | E17: =Inputs!D24 -> 5716 | F17: =E17*$E$3 -> 0 | G17: =E17+F17 -> 5716 | H17: =IF(D17=0,0,G17/D17) -> 0.49978141 | I17: =IF(B17=0,0,G17/B17) -> 0.48065927 | J17: =$G$3 -> 0.65 | K17: =H17-J17 -> -0.15021859 | L17: =IF(H17>J17,"Above target","Within target") -> Within target | M17: =H17-H16 -> 0.046883563
A18: Total | B18: =SUM(B6:B17) -> 93688 | C18: =SUM(C6:C17) -> 87364 | D18: =SUM(D6:D17) -> 90526 | E18: =SUM(E6:E17) -> 56693 | F18: =SUM(F6:F17) -> 0 | G18: =SUM(G6:G17) -> 56693 | H18: =IF(D18=0,0,G18/D18) -> 0.62626207 | I18: =IF(B18=0,0,G18/B18) -> 0.60512552
A20: Summary statistics
A21: All-year weighted LR (sum incurred / sum earned) | F21: =H18 -> 0.62626207
A22: Simple average LR | F22: =AVERAGE(H6:H17) -> 0.64238242
A23: Latest 3-year weighted LR | F23: =SUM(G15:G17)/SUM(D15:D17) -> 0.5194288
A24: Latest 5-year weighted LR | F24: =SUM(G13:G17)/SUM(D13:D17) -> 0.57640034
A25: Standard deviation of LR | F25: =STDEV(H6:H17) -> 0.10596506
A26: Highest LR | F26: =MAX(H6:H17) -> 0.82245509
A27: Year of highest LR | F27: =INDEX(A6:A17,MATCH(MAX(H6:H17),H6:H17,0)) -> 2016
A28: Lowest LR | F28: =MIN(H6:H17) -> 0.45289785
A29: Year of lowest LR | F29: =INDEX(A6:A17,MATCH(MIN(H6:H17),H6:H17,0)) -> 2021
A30: Years above target | F30: =COUNTIF(L6:L17,"Above target") -> 5
A31: Earned premium CAGR (first to last year) | F31: =(D17/D6)^(1/(ROWS(D6:D17)-1))-1 -> 0.063821981
A32: Incurred losses CAGR (first to last year) | F32: =(G17/G6)^(1/(ROWS(G6:G17)-1))-1 -> 0.030965959

Sheet Line_Comparison_2022
A1: Loss Ratio by Line of Business - Canada, 2022
A2: Written-basis loss ratios (claims incurred / written premium); earned premium by line not published. $ millions.
A4: Line of business | B4: Direct Written Premium | C4: Direct Claims Incurred | D4: Direct LR | E4: Net Written Premium | F4: Net Claims Incurred | G4: Net LR | H4: Reinsurance effect (Net - Direct LR)
A5: Total auto | B5: 31357 | C5: 19349 | D5: =IF(B5=0,0,C5/B5) -> 0.6170552 | E5: 26526 | F5: 16323 | G5: =IF(E5=0,0,F5/E5) -> 0.61535852 | H5: =G5-D5 -> -0.0016966868
A6: Auto - private passenger | B6: 25263 | C6: 16216 | D6: =IF(B6=0,0,C6/B6) -> 0.64188735 | E6: 21535 | F6: 13729 | G6: =IF(E6=0,0,F6/E6) -> 0.63752032 | H6: =G6-D6 -> -0.0043670294
A7: Personal property | B7: 17378 | C7: 9868 | D7: =IF(B7=0,0,C7/B7) -> 0.5678444 | E7: 14836 | F7: 8479 | G7: =IF(E7=0,0,F7/E7) -> 0.57151523 | H7: =G7-D7 -> 0.0036708322
A8: Commercial property | B8: 15046 | C8: 6625 | D8: =IF(B8=0,0,C8/B8) -> 0.44031636 | E8: 11892 | F8: 5716 | G8: =IF(E8=0,0,F8/E8) -> 0.48065927 | H8: =G8-D8 -> 0.040342904
A9: Liability | B9: 11531 | C9: 3856 | D9: =IF(B9=0,0,C9/B9) -> 0.33440291 | E9: 8344 | F9: 2644 | G9: =IF(E9=0,0,F9/E9) -> 0.3168744 | H9: =G9-D9 -> -0.017528513
A10: Specialized | B10: 6031 | C10: 1296 | D10: =IF(B10=0,0,C10/B10) -> 0.21488974 | E10: 5056 | F10: 1072 | G10: =IF(E10=0,0,F10/E10) -> 0.21202532 | H10: =G10-D10 -> -0.0028644199
A11: Accident and sickness | B11: 1866 | C11: 953 | D11: =IF(B11=0,0,C11/B11) -> 0.51071811 | E11: 1466 | F11: 879 | G11: =IF(E11=0,0,F11/E11) -> 0.59959072 | H11: =G11-D11 -> 0.088872609
A12: Implied commercial & other auto (Total auto - private passenger) | B12: =B5-B6 -> 6094 | C12: =C5-C6 -> 3133 | D12: =IF(B12=0,0,C12/B12) -> 0.51411224 | E12: =E5-E6 -> 4991 | F12: =F5-F6 -> 2594 | G12: =IF(E12=0,0,F12/E12) -> 0.51973552 | H12: =G12-D12 -> 0.0056232824
A13: Total business (as published) | B13: 83209 | C13: 41946 | D13: =IF(B13=0,0,C13/B13) -> 0.50410412 | E13: 68118 | F13: 35112 | G13: =IF(E13=0,0,F13/E13) -> 0.51545847 | H13: =G13-D13 -> 0.011354346
A14: Check: sum of lines (excl. sub-line) - published total | B14: =SUM(B5,B7:B11)-B13 -> 0 | C14: =SUM(C5,C7:C11)-C13 -> 1 | E14: =SUM(E5,E7:E11)-E13 -> 2 | F14: =SUM(F5,F7:F11)-F13 -> 1
A15: Small differences are due to rounding in the published tables.
A17: Source: Insurance Bureau of Canada (IBC), Facts of the Property and Casualty Insurance Industry in Canada 2023, Section 1, pp. 9 & 11 (data: IBC, MSA Research, SCOR, AMF). https://ibc.ca/industry-resources/resources-data/facts-book

Sheet Benchmarks
A1: Model Validation - Published Commercial Property Loss Ratios
A2: Compares the model's earned-basis loss ratio with ratios quoted by industry bodies. Bases differ slightly.
A4: Year | B4: Published LR | C4: Model LR | D4: Difference | E4: Published by | F4: URL
A5: 2012 | B5: 0.62 | C5: =INDEX(LR_Model!$H$6:$H$17,MATCH(A5,LR_Model!$A$6:$A$17,0)) -> 0.65530864 | D5: =C5-B5 -> 0.035308642 | E5: IBC (Swiss Re Canada Outlook, 2014) via Canadian Underwriter | F5: https://canadianunderwriter.ca/2014/03/31/ibc-says-weather-hit-pc-insurers-results-hard-in-2013/
A6: 2013 | B6: 0.77 | C6: =INDEX(LR_Model!$H$6:$H$17,MATCH(A6,LR_Model!$A$6:$A$17,0)) -> 0.75334669 | D6: =C6-B6 -> -0.016653307 | E6: IBC (Swiss Re Canada Outlook, 2014) via Canadian Underwriter | F6: https://canadianunderwriter.ca/2014/03/31/ibc-says-weather-hit-pc-insurers-results-hard-in-2013/
A7: 2020 | B7: 0.616 | C7: =INDEX(LR_Model!$H$6:$H$17,MATCH(A7,LR_Model!$A$6:$A$17,0)) -> 0.62200957 | D7: =C7-B7 -> 0.0060095694 | E7: PACICC Solvency Matters via Canadian Underwriter | F7: https://canadianunderwriter.ca/2022/04/07/how-profitable-was-canadas-pc-industry-last-year/
A8: 2021 | B8: 0.454 | C8: =INDEX(LR_Model!$H$6:$H$17,MATCH(A8,LR_Model!$A$6:$A$17,0)) -> 0.45289785 | D8: =C8-B8 -> -0.0011021516 | E8: PACICC Solvency Matters via Canadian Underwriter | F8: https://canadianunderwriter.ca/2022/04/07/how-profitable-was-canadas-pc-industry-last-year/
A10: Mean absolute difference: | D10: =SUMPRODUCT(ABS(D5:D8))/COUNT(D5:D8) -> 0.014768417
A12: Interpretation: the model reproduces published ratios within a few points, which supports the 50% earning assumption. Remaining gaps reflect rounding and differences in premium basis.

Sheet Calculator
B1: Loss Ratio Calculator - Your Own Book
B2: Replace the yellow example values with your portfolio's figures (any currency unit, e.g. $).
B4: Item | C4: Amount | D4: Explanation
B5: Earned premium | C5: 10000000 | D5: Premium earned in the period (written premium adjusted for UPR change).
B6: Paid losses (indemnity) | C6: 4200000 | D6: Claims paid in the period.
B7: Change in case reserves | C7: 600000 | D7: Closing case reserves less opening case reserves.
B8: Change in IBNR | C8: 400000 | D8: Closing IBNR less opening IBNR.
B9: Incurred losses | C9: =C6+C7+C8 -> 5200000 | D9: Paid + change in case + change in IBNR.
B10: Allocated LAE (ALAE) | C10: 350000 | D10: Claim-specific expenses: legal, adjusters, experts.
B11: Unallocated LAE (ULAE) | C11: 250000 | D11: Claims department overhead.
B12: Incurred losses + LAE | C12: =C9+C10+C11 -> 5800000
B14: Pure loss ratio | C14: =IF(C5=0,0,C9/C5) -> 0.52 | D14: Incurred losses / earned premium.
B15: LAE ratio | C15: =IF(C5=0,0,(C10+C11)/C5) -> 0.06 | D15: (ALAE + ULAE) / earned premium.
B16: Loss ratio incl. LAE | C16: =IF(C5=0,0,C12/C5) -> 0.58 | D16: The headline loss ratio most actuaries report.
B17: Underwriting expense ratio | C17: 0.3 | D17: Commissions, premium tax, general expenses / premium.
B18: Combined ratio | C18: =C16+C17 -> 0.88 | D18: Below 100% = underwriting profit.
B19: Underwriting profit / (loss) | C19: =C5*(1-C18) -> 1200000 | D19: Earned premium x (1 - combined ratio).
B21: Target loss ratio (from Inputs) | C21: =Inputs!C7 -> 0.65 | D21: Linked from the Inputs sheet.
B22: Result vs target | C22: =IF(C16>C21,"Above target - review pricing","Within target") -> Within target
B23: Industry benchmark: latest 5-yr weighted LR | C23: =LR_Model!F24 -> 0.57640034 | D23: Canadian commercial property, 2018-2022.
B25: Example values are illustrative, not from any real insurer.

Sheet Triangle_Data
A1: Loss Development Triangles - Commercial Property ($mm, cumulative)
A2: ILLUSTRATIVE / SIMULATED: industry accident-year triangles are not published for Canada. Values are simulated from the model's earned premium and calendar-year loss ratios with an assumed commercial property development pattern. Replace the blue cells with your own company data.
A5: Cumulative paid losses
A6: Accident Year | B6: 12 mo | C6: 24 mo | D6: 36 mo | E6: 48 mo | F6: 60 mo | G6: 72 mo | H6: 84 mo | I6: 96 mo | J6: 108 mo | K6: 120 mo | L6: Simulated true ultimate
A7: 2013 | B7: 2549 | C7: 3850 | D7: 4149 | E7: 4482 | F7: 4606 | G7: 4656 | H7: 4671 | I7: 4688 | J7: 4694 | K7: 4699 | L7: 4699
A8: 2014 | B8: 2035 | C8: 3003 | D8: 3600 | E8: 3737 | F8: 3869 | G8: 3926 | H8: 3941 | I8: 3949 | J8: 3951 | L8: 3955
A9: 2015 | B9: 2031 | C9: 2983 | D9: 3383 | E9: 3632 | F9: 3724 | G9: 3776 | H9: 3777 | I9: 3792 | L9: 3797
A10: 2016 | B10: 2320 | C10: 4343 | D10: 4997 | E10: 5218 | F10: 5396 | G10: 5436 | H10: 5472 | L10: 5494
A11: 2017 | B11: 2350 | C11: 3312 | D11: 3883 | E11: 4084 | F11: 4182 | G11: 4229 | L11: 4280
A12: 2018 | B12: 2718 | C12: 4439 | D12: 4903 | E12: 5200 | F12: 5370 | L12: 5471
A13: 2019 | B13: 2711 | C13: 4012 | D13: 4471 | E13: 4704 | L13: 5015
A14: 2020 | B14: 2891 | C14: 4412 | D14: 5106 | L14: 5525
A15: 2021 | B15: 2554 | C15: 3681 | L15: 4673
A16: 2022 | B16: 2939 | L16: 5716
A18: Cumulative reported (case-incurred) losses
A19: Accident Year | B19: 12 mo | C19: 24 mo | D19: 36 mo | E19: 48 mo | F19: 60 mo | G19: 72 mo | H19: 84 mo | I19: 96 mo | J19: 108 mo | K19: 120 mo
A20: 2013 | B20: 3942 | C20: 4522 | D20: 4688 | E20: 4755 | F20: 4717 | G20: 4707 | H20: 4698 | I20: 4697 | J20: 4699 | K20: 4699
A21: 2014 | B21: 3336 | C21: 3917 | D21: 3861 | E21: 3921 | F21: 3968 | G21: 3980 | H21: 3950 | I21: 3953 | J21: 3955
A22: 2015 | B22: 3123 | C22: 3563 | D22: 3780 | E22: 3763 | F22: 3773 | G22: 3803 | H22: 3794 | I22: 3798
A23: 2016 | B23: 4608 | C23: 5315 | D23: 5378 | E23: 5445 | F23: 5479 | G23: 5503 | H23: 5482
A24: 2017 | B24: 3622 | C24: 4100 | D24: 4310 | E24: 4216 | F24: 4286 | G24: 4288
A25: 2018 | B25: 4321 | C25: 5500 | D25: 5332 | E25: 5431 | F25: 5527
A26: 2019 | B26: 4475 | C26: 4942 | D26: 4984 | E26: 4968
A27: 2020 | B27: 4066 | C27: 5424 | D27: 5624
A28: 2021 | B28: 3848 | C28: 4437
A29: 2022 | B29: 4813
A31: Case reserves (reported - paid)
A32: Accident Year | B32: 12 mo | C32: 24 mo | D32: 36 mo | E32: 48 mo | F32: 60 mo | G32: 72 mo | H32: 84 mo | I32: 96 mo | J32: 108 mo | K32: 120 mo
A33: 2013 | B33: =B20-B7 -> 1393 | C33: =C20-C7 -> 672 | D33: =D20-D7 -> 539 | E33: =E20-E7 -> 273 | F33: =F20-F7 -> 111 | G33: =G20-G7 -> 51 | H33: =H20-H7 -> 27 | I33: =I20-I7 -> 9 | ... K33: =K20-K7 -> 0
A34: 2014 | B34: =B21-B8 -> 1301 | C34: =C21-C8 -> 914 | D34: =D21-D8 -> 261 | E34: =E21-E8 -> 184 | F34: =F21-F8 -> 99 | G34: =G21-G8 -> 54 | H34: =H21-H8 -> 9 | I34: =I21-I8 -> 4 | J34: =J21-J8 -> 4
A35: 2015 | B35: =B22-B9 -> 1092 | C35: =C22-C9 -> 580 | D35: =D22-D9 -> 397 | E35: =E22-E9 -> 131 | F35: =F22-F9 -> 49 | G35: =G22-G9 -> 27 | H35: =H22-H9 -> 17 | I35: =I22-I9 -> 6
A36: 2016 | B36: =B23-B10 -> 2288 | C36: =C23-C10 -> 972 | D36: =D23-D10 -> 381 | E36: =E23-E10 -> 227 | F36: =F23-F10 -> 83 | G36: =G23-G10 -> 67 | H36: =H23-H10 -> 10
A37: 2017 | B37: =B24-B11 -> 1272 | C37: =C24-C11 -> 788 | D37: =D24-D11 -> 427 | E37: =E24-E11 -> 132 | F37: =F24-F11 -> 104 | G37: =G24-G11 -> 59
A38: 2018 | B38: =B25-B12 -> 1603 | C38: =C25-C12 -> 1061 | D38: =D25-D12 -> 429 | E38: =E25-E12 -> 231 | F38: =F25-F12 -> 157
A39: 2019 | B39: =B26-B13 -> 1764 | C39: =C26-C13 -> 930 | D39: =D26-D13 -> 513 | E39: =E26-E13 -> 264
A40: 2020 | B40: =B27-B14 -> 1175 | C40: =C27-C14 -> 1012 | D40: =D27-D14 -> 518
A41: 2021 | B41: =B28-B15 -> 1294 | C41: =C28-C15 -> 756
A42: 2022 | B42: =B29-B16 -> 1874
A45: Shaded cells = latest diagonal (valuation 31-Dec-2022).

Sheet Chain_Ladder
A1: Chain-Ladder Development - Paid and Reported
A2: Age-to-age factors, averages, selected LDFs and cumulative development factors (CDFs).
A4: LDF averaging method (1-4) | B4: 2 | C4: 1 = simple average, 2 = volume-weighted all years, 3 = volume-weighted latest 5, 4 = volume-weighted latest 3
A5: Paid tail factor (120 mo - ult) | B5: 1 | C5: Commercial property is short-tailed; 1.000 assumes no development after 10 years.
A6: Reported tail factor (120 mo - ult) | B6: 1
A8: Paid - age-to-age factors
A9: Accident Year | B9: 12-24 | C9: 24-36 | D9: 36-48 | E9: 48-60 | F9: 60-72 | G9: 72-84 | H9: 84-96 | I9: 96-108 | J9: 108-120 | K9: 120-Ult
A10: =Triangle_Data!A7 -> 2013 | B10: =Triangle_Data!C7/Triangle_Data!B7 -> 1.5103962 | C10: =Triangle_Data!D7/Triangle_Data!C7 -> 1.0776623 | D10: =Triangle_Data!E7/Triangle_Data!D7 -> 1.0802603 | E10: =Triangle_Data!F7/Triangle_Data!E7 -> 1.0276662 | F10: =Triangle_Data!G7/Triangle_Data!F7 -> 1.0108554 | G10: =Triangle_Data!H7/Triangle_Data!G7 -> 1.0032216 | H10: =Triangle_Data!I7/Triangle_Data!H7 -> 1.0036395 | I10: =Triangle_Data!J7/Triangle_Data!I7 -> 1.0012799 | J10: =Triangle_Data!K7/Triangle_Data!J7 -> 1.0010652
A11: =Triangle_Data!A8 -> 2014 | B11: =Triangle_Data!C8/Triangle_Data!B8 -> 1.4756757 | C11: =Triangle_Data!D8/Triangle_Data!C8 -> 1.1988012 | D11: =Triangle_Data!E8/Triangle_Data!D8 -> 1.0380556 | E11: =Triangle_Data!F8/Triangle_Data!E8 -> 1.0353225 | F11: =Triangle_Data!G8/Triangle_Data!F8 -> 1.0147325 | G11: =Triangle_Data!H8/Triangle_Data!G8 -> 1.0038207 | H11: =Triangle_Data!I8/Triangle_Data!H8 -> 1.0020299 | I11: =Triangle_Data!J8/Triangle_Data!I8 -> 1.0005065
A12: =Triangle_Data!A9 -> 2015 | B12: =Triangle_Data!C9/Triangle_Data!B9 -> 1.4687346 | C12: =Triangle_Data!D9/Triangle_Data!C9 -> 1.1340932 | D12: =Triangle_Data!E9/Triangle_Data!D9 -> 1.0736033 | E12: =Triangle_Data!F9/Triangle_Data!E9 -> 1.0253304 | F12: =Triangle_Data!G9/Triangle_Data!F9 -> 1.0139635 | G12: =Triangle_Data!H9/Triangle_Data!G9 -> 1.0002648 | H12: =Triangle_Data!I9/Triangle_Data!H9 -> 1.0039714
A13: =Triangle_Data!A10 -> 2016 | B13: =Triangle_Data!C10/Triangle_Data!B10 -> 1.8719828 | C13: =Triangle_Data!D10/Triangle_Data!C10 -> 1.1505872 | D13: =Triangle_Data!E10/Triangle_Data!D10 -> 1.0442265 | E13: =Triangle_Data!F10/Triangle_Data!E10 -> 1.0341127 | F13: =Triangle_Data!G10/Triangle_Data!F10 -> 1.0074129 | G13: =Triangle_Data!H10/Triangle_Data!G10 -> 1.0066225
A14: =Triangle_Data!A11 -> 2017 | B14: =Triangle_Data!C11/Triangle_Data!B11 -> 1.4093617 | C14: =Triangle_Data!D11/Triangle_Data!C11 -> 1.1724034 | D14: =Triangle_Data!E11/Triangle_Data!D11 -> 1.0517641 | E14: =Triangle_Data!F11/Triangle_Data!E11 -> 1.0239961 | F14: =Triangle_Data!G11/Triangle_Data!F11 -> 1.0112386
A15: =Triangle_Data!A12 -> 2018 | B15: =Triangle_Data!C12/Triangle_Data!B12 -> 1.6331862 | C15: =Triangle_Data!D12/Triangle_Data!C12 -> 1.104528 | D15: =Triangle_Data!E12/Triangle_Data!D12 -> 1.0605752 | E15: =Triangle_Data!F12/Triangle_Data!E12 -> 1.0326923
A16: =Triangle_Data!A13 -> 2019 | B16: =Triangle_Data!C13/Triangle_Data!B13 -> 1.4798967 | C16: =Triangle_Data!D13/Triangle_Data!C13 -> 1.1144068 | D16: =Triangle_Data!E13/Triangle_Data!D13 -> 1.0521136
A17: =Triangle_Data!A14 -> 2020 | B17: =Triangle_Data!C14/Triangle_Data!B14 -> 1.5261155 | C17: =Triangle_Data!D14/Triangle_Data!C14 -> 1.1572983
A18: =Triangle_Data!A15 -> 2021 | B18: =Triangle_Data!C15/Triangle_Data!B15 -> 1.4412686
A19: =Triangle_Data!A16 -> 2022
B20: 12 mo | C20: 24 mo | D20: 36 mo | E20: 48 mo | F20: 60 mo | G20: 72 mo | H20: 84 mo | I20: 96 mo | J20: 108 mo | K20: 120 mo
A21: Simple average | B21: =AVERAGE(B10:B18) -> 1.5351798 | C21: =AVERAGE(C10:C17) -> 1.1387225 | D21: =AVERAGE(D10:D16) -> 1.0572284 | E21: =AVERAGE(E10:E15) -> 1.0298534 | F21: =AVERAGE(F10:F14) -> 1.0116406 | G21: =AVERAGE(G10:G13) -> 1.0034824 | H21: =AVERAGE(H10:H12) -> 1.0032136 | I21: =AVERAGE(I10:I11) -> 1.0008932 | J21: =AVERAGE(J10:J10) -> 1.0010652
A22: Vol-weighted all years | B22: =SUM(Triangle_Data!C7:C15)/SUM(Triangle_Data!B7:B15) -> 1.5359448 | C22: =SUM(Triangle_Data!D7:D14)/SUM(Triangle_Data!C7:C14) -> 1.1363247 | D22: =SUM(Triangle_Data!E7:E13)/SUM(Triangle_Data!D7:D13) -> 1.0568638 | E22: =SUM(Triangle_Data!F7:F12)/SUM(Triangle_Data!E7:E12) -> 1.0301294 | F22: =SUM(Triangle_Data!G7:G11)/SUM(Triangle_Data!F7:F11) -> 1.0112963 | G22: =SUM(Triangle_Data!H7:H10)/SUM(Triangle_Data!G7:G10) -> 1.0037653 | H22: =SUM(Triangle_Data!I7:I9)/SUM(Triangle_Data!H7:H9) -> 1.0032287 | I22: =SUM(Triangle_Data!J7:J8)/SUM(Triangle_Data!I7:I8) -> 1.0009262 | J22: =SUM(Triangle_Data!K7:K7)/SUM(Triangle_Data!J7:J7) -> 1.0010652
A23: Vol-weighted latest 5 | B23: =SUM(Triangle_Data!C11:C15)/SUM(Triangle_Data!B11:B15) -> 1.5015124 | C23: =SUM(Triangle_Data!D10:D14)/SUM(Triangle_Data!C10:C14) -> 1.1385125 | D23: =SUM(Triangle_Data!E9:E13)/SUM(Triangle_Data!D9:D13) -> 1.0555068 | E23: =SUM(Triangle_Data!F8:F12)/SUM(Triangle_Data!E8:E12) -> 1.0306342 | F23: =SUM(Triangle_Data!G7:G11)/SUM(Triangle_Data!F7:F11) -> 1.0112963 | G23: =SUM(Triangle_Data!H7:H10)/SUM(Triangle_Data!G7:G10) -> 1.0037653 | H23: =SUM(Triangle_Data!I7:I9)/SUM(Triangle_Data!H7:H9) -> 1.0032287 | I23: =SUM(Triangle_Data!J7:J8)/SUM(Triangle_Data!I7:I8) -> 1.0009262 | J23: =SUM(Triangle_Data!K7:K7)/SUM(Triangle_Data!J7:J7) -> 1.0010652
A24: Vol-weighted latest 3 | B24: =SUM(Triangle_Data!C13:C15)/SUM(Triangle_Data!B13:B15) -> 1.4841834 | C24: =SUM(Triangle_Data!D12:D14)/SUM(Triangle_Data!C12:C14) -> 1.1257094 | D24: =SUM(Triangle_Data!E11:E13)/SUM(Triangle_Data!D11:D13) -> 1.0551407 | E24: =SUM(Triangle_Data!F10:F12)/SUM(Triangle_Data!E10:E12) -> 1.0307544 | F24: =SUM(Triangle_Data!G9:G11)/SUM(Triangle_Data!F9:F11) -> 1.0104496 | G24: =SUM(Triangle_Data!H8:H10)/SUM(Triangle_Data!G8:G10) -> 1.003958 | H24: =SUM(Triangle_Data!I7:I9)/SUM(Triangle_Data!H7:H9) -> 1.0032287 | I24: =SUM(Triangle_Data!J7:J8)/SUM(Triangle_Data!I7:I8) -> 1.0009262 | J24: =SUM(Triangle_Data!K7:K7)/SUM(Triangle_Data!J7:J7) -> 1.0010652
A25: Selected LDF | B25: =CHOOSE($B$4,B21,B22,B23,B24) -> 1.5359448 | C25: =CHOOSE($B$4,C21,C22,C23,C24) -> 1.1363247 | D25: =CHOOSE($B$4,D21,D22,D23,D24) -> 1.0568638 | E25: =CHOOSE($B$4,E21,E22,E23,E24) -> 1.0301294 | F25: =CHOOSE($B$4,F21,F22,F23,F24) -> 1.0112963 | G25: =CHOOSE($B$4,G21,G22,G23,G24) -> 1.0037653 | H25: =CHOOSE($B$4,H21,H22,H23,H24) -> 1.0032287 | I25: =CHOOSE($B$4,I21,I22,I23,I24) -> 1.0009262 | J25: =CHOOSE($B$4,J21,J22,J23,J24) -> 1.0010652 | K25: =$B$5 -> 1
A26: CDF to ultimate | B26: =B25*C26 -> 1.9389376 | C26: =C25*D26 -> 1.2623746 | D26: =D25*E26 -> 1.1109277 | E26: =E25*F26 -> 1.051155 | F26: =F25*G26 -> 1.0204107 | G26: =G25*H26 -> 1.0090125 | H26: =H25*I26 -> 1.0052275 | I26: =I25*J26 -> 1.0019924 | J26: =J25*K26 -> 1.0010652 | K26: =K25 -> 1
A27: % of ultimate | B27: =IF(B26=0,0,1/B26) -> 0.51574635 | C27: =IF(C26=0,0,1/C26) -> 0.7921579 | D27: =IF(D26=0,0,1/D26) -> 0.90014859 | E27: =IF(E26=0,0,1/E26) -> 0.95133447 | F27: =IF(F26=0,0,1/F26) -> 0.97999761 | G27: =IF(G26=0,0,1/G26) -> 0.99106798 | H27: =IF(H26=0,0,1/H26) -> 0.99479966 | I27: =IF(I26=0,0,1/I26) -> 0.99801154 | ... K27: =IF(K26=0,0,1/K26) -> 1
A29: Reported - age-to-age factors
A30: Accident Year | B30: 12-24 | C30: 24-36 | D30: 36-48 | E30: 48-60 | F30: 60-72 | G30: 72-84 | H30: 84-96 | I30: 96-108 | J30: 108-120 | K30: 120-Ult
A31: =Triangle_Data!A20 -> 2013 | B31: =Triangle_Data!C20/Triangle_Data!B20 -> 1.1471334 | C31: =Triangle_Data!D20/Triangle_Data!C20 -> 1.0367094 | D31: =Triangle_Data!E20/Triangle_Data!D20 -> 1.0142918 | E31: =Triangle_Data!F20/Triangle_Data!E20 -> 0.99200841 | F31: =Triangle_Data!G20/Triangle_Data!F20 -> 0.99788001 | G31: =Triangle_Data!H20/Triangle_Data!G20 -> 0.99808795 | H31: =Triangle_Data!I20/Triangle_Data!H20 -> 0.99978714 | I31: =Triangle_Data!J20/Triangle_Data!I20 -> 1.0004258 | J31: =Triangle_Data!K20/Triangle_Data!J20 -> 1
A32: =Triangle_Data!A21 -> 2014 | B32: =Triangle_Data!C21/Triangle_Data!B21 -> 1.1741607 | C32: =Triangle_Data!D21/Triangle_Data!C21 -> 0.98570334 | D32: =Triangle_Data!E21/Triangle_Data!D21 -> 1.01554 | E32: =Triangle_Data!F21/Triangle_Data!E21 -> 1.0119867 | F32: =Triangle_Data!G21/Triangle_Data!F21 -> 1.0030242 | G32: =Triangle_Data!H21/Triangle_Data!G21 -> 0.99246231 | H32: =Triangle_Data!I21/Triangle_Data!H21 -> 1.0007595 | I32: =Triangle_Data!J21/Triangle_Data!I21 -> 1.0005059
A33: =Triangle_Data!A22 -> 2015 | B33: =Triangle_Data!C22/Triangle_Data!B22 -> 1.1408902 | C33: =Triangle_Data!D22/Triangle_Data!C22 -> 1.0609037 | D33: =Triangle_Data!E22/Triangle_Data!D22 -> 0.99550265 | E33: =Triangle_Data!F22/Triangle_Data!E22 -> 1.0026575 | F33: =Triangle_Data!G22/Triangle_Data!F22 -> 1.0079512 | G33: =Triangle_Data!H22/Triangle_Data!G22 -> 0.99763345 | H33: =Triangle_Data!I22/Triangle_Data!H22 -> 1.0010543
A34: =Triangle_Data!A23 -> 2016 | B34: =Triangle_Data!C23/Triangle_Data!B23 -> 1.1534288 | C34: =Triangle_Data!D23/Triangle_Data!C23 -> 1.0118532 | D34: =Triangle_Data!E23/Triangle_Data!D23 -> 1.0124582 | E34: =Triangle_Data!F23/Triangle_Data!E23 -> 1.0062443 | F34: =Triangle_Data!G23/Triangle_Data!F23 -> 1.0043804 | G34: =Triangle_Data!H23/Triangle_Data!G23 -> 0.9961839
A35: =Triangle_Data!A24 -> 2017 | B35: =Triangle_Data!C24/Triangle_Data!B24 -> 1.1319713 | C35: =Triangle_Data!D24/Triangle_Data!C24 -> 1.0512195 | D35: =Triangle_Data!E24/Triangle_Data!D24 -> 0.97819026 | E35: =Triangle_Data!F24/Triangle_Data!E24 -> 1.0166034 | F35: =Triangle_Data!G24/Triangle_Data!F24 -> 1.0004666
A36: =Triangle_Data!A25 -> 2018 | B36: =Triangle_Data!C25/Triangle_Data!B25 -> 1.2728535 | C36: =Triangle_Data!D25/Triangle_Data!C25 -> 0.96945455 | D36: =Triangle_Data!E25/Triangle_Data!D25 -> 1.0185671 | E36: =Triangle_Data!F25/Triangle_Data!E25 -> 1.0176763
A37: =Triangle_Data!A26 -> 2019 | B37: =Triangle_Data!C26/Triangle_Data!B26 -> 1.1043575 | C37: =Triangle_Data!D26/Triangle_Data!C26 -> 1.0084986 | D37: =Triangle_Data!E26/Triangle_Data!D26 -> 0.99678973
A38: =Triangle_Data!A27 -> 2020 | B38: =Triangle_Data!C27/Triangle_Data!B27 -> 1.3339892 | C38: =Triangle_Data!D27/Triangle_Data!C27 -> 1.0368732
A39: =Triangle_Data!A28 -> 2021 | B39: =Triangle_Data!C28/Triangle_Data!B28 -> 1.1530665
A40: =Triangle_Data!A29 -> 2022
B41: 12 mo | C41: 24 mo | D41: 36 mo | E41: 48 mo | F41: 60 mo | G41: 72 mo | H41: 84 mo | I41: 96 mo | J41: 108 mo | K41: 120 mo
A42: Simple average | B42: =AVERAGE(B31:B39) -> 1.1790946 | C42: =AVERAGE(C31:C38) -> 1.0201519 | D42: =AVERAGE(D31:D37) -> 1.0044771 | E42: =AVERAGE(E31:E36) -> 1.0078628 | F42: =AVERAGE(F31:F35) -> 1.0027405 | G42: =AVERAGE(G31:G34) -> 0.9960919 | H42: =AVERAGE(H31:H33) -> 1.0005336 | I42: =AVERAGE(I31:I32) -> 1.0004659 | J42: =AVERAGE(J31:J31) -> 1
A43: Vol-weighted all years | B43: =SUM(Triangle_Data!C20:C28)/SUM(Triangle_Data!B20:B28) -> 1.1804986 | C43: =SUM(Triangle_Data!D20:D27)/SUM(Triangle_Data!C20:C27) -> 1.0180779 | D43: =SUM(Triangle_Data!E20:E26)/SUM(Triangle_Data!D20:D26) -> 1.0051341 | E43: =SUM(Triangle_Data!F20:F25)/SUM(Triangle_Data!E20:E25) -> 1.0079547 | F43: =SUM(Triangle_Data!G20:G24)/SUM(Triangle_Data!F20:F24) -> 1.0026099 | G43: =SUM(Triangle_Data!H20:H23)/SUM(Triangle_Data!G20:G23) -> 0.99616518 | H43: =SUM(Triangle_Data!I20:I22)/SUM(Triangle_Data!H20:H22) -> 1.0004822 | I43: =SUM(Triangle_Data!J20:J21)/SUM(Triangle_Data!I20:I21) -> 1.0004624 | J43: =SUM(Triangle_Data!K20:K20)/SUM(Triangle_Data!J20:J20) -> 1
...

Sheet Reserve_Summary
A1: Ultimate Losses & Reserves - Chain-Ladder and Bornhuetter-Ferguson
A2: Valuation date 31-Dec-2022, $ millions. Triangles are illustrative (see Triangle_Data).
A4: BF a priori expected LR | D4: 0.62 | E4: Initial loss ratio expectation, e.g. the long-run industry LR (LR_Model all-year weighted is 62.6%).
A5: Selected method (1-3) | D5: 2 | E5: 1 = paid chain-ladder, 2 = reported chain-ladder, 3 = Bornhuetter-Ferguson (reported)
A7: Accident Year | B7: Earned Premium | C7: Paid to Date | D7: Reported to Date | E7: Case Reserves | F7: Age (mo) | G7: Paid CDF | H7: Reported CDF | I7: Ult - Paid CL | J7: Ult - Reported CL | K7: Ult - BF | L7: Selected Ultimate | M7: IBNR | N7: Total Unpaid | O7: Ultimate LR | P7: vs Simulated True
A8: =Triangle_Data!A7 -> 2013 | B8: =INDEX(LR_Model!$D$6:$D$17,MATCH(A8,LR_Model!$A$6:$A$17,0)) -> 6237.5 | C8: =Triangle_Data!K7 -> 4699 | D8: =Triangle_Data!K20 -> 4699 | E8: =D8-C8 -> 0 | F8: 120 | G8: =Chain_Ladder!K26 -> 1 | H8: =Chain_Ladder!K47 -> 1 | I8: =C8*G8 -> 4699 | J8: =D8*H8 -> 4699 | K8: =D8+B8*$D$4*(1-1/H8) -> 4699 | L8: =CHOOSE($D$5,I8,J8,K8) -> 4699 | M8: =L8-D8 -> 0 | N8: =L8-C8 -> 0 | O8: =IF(B8=0,0,L8/B8) -> 0.75334669 | P8: =L8-Triangle_Data!L7 -> 0
A9: =Triangle_Data!A8 -> 2014 | B9: =INDEX(LR_Model!$D$6:$D$17,MATCH(A9,LR_Model!$A$6:$A$17,0)) -> 6480 | C9: =Triangle_Data!J8 -> 3951 | D9: =Triangle_Data!J21 -> 3955 | E9: =D9-C9 -> 4 | F9: 108 | G9: =Chain_Ladder!J26 -> 1.0010652 | H9: =Chain_Ladder!J47 -> 1 | I9: =C9*G9 -> 3955.2086 | J9: =D9*H9 -> 3955 | K9: =D9+B9*$D$4*(1-1/H9) -> 3955 | L9: =CHOOSE($D$5,I9,J9,K9) -> 3955 | M9: =L9-D9 -> 0 | N9: =L9-C9 -> 4 | O9: =IF(B9=0,0,L9/B9) -> 0.61033951 | P9: =L9-Triangle_Data!L8 -> 0
A10: =Triangle_Data!A9 -> 2015 | B10: =INDEX(LR_Model!$D$6:$D$17,MATCH(A10,LR_Model!$A$6:$A$17,0)) -> 6638.5 | C10: =Triangle_Data!I9 -> 3792 | D10: =Triangle_Data!I22 -> 3798 | E10: =D10-C10 -> 6 | F10: 96 | G10: =Chain_Ladder!I26 -> 1.0019924 | H10: =Chain_Ladder!I47 -> 1.0004624 | I10: =C10*G10 -> 3799.5553 | J10: =D10*H10 -> 3799.7563 | K10: =D10+B10*$D$4*(1-1/H10) -> 3799.9024 | L10: =CHOOSE($D$5,I10,J10,K10) -> 3799.7563 | M10: =L10-D10 -> 1.7563006 | N10: =L10-C10 -> 7.7563006 | O10: =IF(B10=0,0,L10/B10) -> 0.57238176 | P10: =L10-Triangle_Data!L9 -> 2.7563006
A11: =Triangle_Data!A10 -> 2016 | B11: =INDEX(LR_Model!$D$6:$D$17,MATCH(A11,LR_Model!$A$6:$A$17,0)) -> 6680 | C11: =Triangle_Data!H10 -> 5472 | D11: =Triangle_Data!H23 -> 5482 | E11: =D11-C11 -> 10 | F11: 84 | G11: =Chain_Ladder!H26 -> 1.0052275 | H11: =Chain_Ladder!H47 -> 1.0009449 | I11: =C11*G11 -> 5500.605 | J11: =D11*H11 -> 5487.1799 | K11: =D11+B11*$D$4*(1-1/H11) -> 5485.9097 | L11: =CHOOSE($D$5,I11,J11,K11) -> 5487.1799 | M11: =L11-D11 -> 5.1798778 | N11: =L11-C11 -> 15.179878 | O11: =IF(B11=0,0,L11/B11) -> 0.82143411 | P11: =L11-Triangle_Data!L10 -> -6.8201222
A12: =Triangle_Data!A11 -> 2017 | B12: =INDEX(LR_Model!$D$6:$D$17,MATCH(A12,LR_Model!$A$6:$A$17,0)) -> 6822.5 | C12: =Triangle_Data!G11 -> 4229 | D12: =Triangle_Data!G24 -> 4288 | E12: =D12-C12 -> 59 | F12: 72 | G12: =Chain_Ladder!G26 -> 1.0090125 | H12: =Chain_Ladder!G47 -> 0.99710644 | I12: =C12*G12 -> 4267.114 | J12: =D12*H12 -> 4275.5924 | K12: =D12+B12*$D$4*(1-1/H12) -> 4275.7249 | L12: =CHOOSE($D$5,I12,J12,K12) -> 4275.5924 | M12: =L12-D12 -> -12.407584 | N12: =L12-C12 -> 46.592416 | O12: =IF(B12=0,0,L12/B12) -> 0.62668998 | P12: =L12-Triangle_Data!L11 -> -4.4075845
A13: =Triangle_Data!A12 -> 2018 | B13: =INDEX(LR_Model!$D$6:$D$17,MATCH(A13,LR_Model!$A$6:$A$17,0)) -> 7289.5 | C13: =Triangle_Data!F12 -> 5370 | D13: =Triangle_Data!F25 -> 5527 | E13: =D13-C13 -> 157 | F13: 60 | G13: =Chain_Ladder!F26 -> 1.0204107 | H13: =Chain_Ladder!F47 -> 0.9997088 | I13: =C13*G13 -> 5479.6052 | J13: =D13*H13 -> 5525.3905 | K13: =D13+B13*$D$4*(1-1/H13) -> 5525.6835 | L13: =CHOOSE($D$5,I13,J13,K13) -> 5525.3905 | M13: =L13-D13 -> -1.6094794 | N13: =L13-C13 -> 155.39052 | O13: =IF(B13=0,0,L13/B13) -> 0.75799308 | P13: =L13-Triangle_Data!L12 -> 54.390521
A14: =Triangle_Data!A13 -> 2019 | B14: =INDEX(LR_Model!$D$6:$D$17,MATCH(A14,LR_Model!$A$6:$A$17,0)) -> 7874.5 | C14: =Triangle_Data!E13 -> 4704 | D14: =Triangle_Data!E26 -> 4968 | E14: =D14-C14 -> 264 | F14: 48 | G14: =Chain_Ladder!E26 -> 1.051155 | H14: =Chain_Ladder!E47 -> 1.0076611 | I14: =C14*G14 -> 4944.6332 | J14: =D14*H14 -> 5006.0606 | K14: =D14+B14*$D$4*(1-1/H14) -> 5005.1188 | L14: =CHOOSE($D$5,I14,J14,K14) -> 5006.0606 | M14: =L14-D14 -> 38.060592 | N14: =L14-C14 -> 302.06059 | O14: =IF(B14=0,0,L14/B14) -> 0.6357306 | P14: =L14-Triangle_Data!L13 -> -8.9394079
A15: =Triangle_Data!A14 -> 2020 | B15: =INDEX(LR_Model!$D$6:$D$17,MATCH(A15,LR_Model!$A$6:$A$17,0)) -> 8882.5 | C15: =Triangle_Data!D14 -> 5106 | D15: =Triangle_Data!D27 -> 5624 | E15: =D15-C15 -> 518 | F15: 36 | G15: =Chain_Ladder!D26 -> 1.1109277 | H15: =Chain_Ladder!D47 -> 1.0128346 | I15: =C15*G15 -> 5672.3968 | J15: =D15*H15 -> 5696.1815 | K15: =D15+B15*$D$4*(1-1/H15) -> 5693.7862 | L15: =CHOOSE($D$5,I15,J15,K15) -> 5696.1815 | M15: =L15-D15 -> 72.181544 | N15: =L15-C15 -> 590.18154 | O15: =IF(B15=0,0,L15/B15) -> 0.64128134 | P15: =L15-Triangle_Data!L14 -> 171.18154
A16: =Triangle_Data!A15 -> 2021 | B16: =INDEX(LR_Model!$D$6:$D$17,MATCH(A16,LR_Model!$A$6:$A$17,0)) -> 10318 | C16: =Triangle_Data!C15 -> 3681 | D16: =Triangle_Data!C28 -> 4437 | E16: =D16-C16 -> 756 | F16: 24 | G16: =Chain_Ladder!C26 -> 1.2623746 | H16: =Chain_Ladder!C47 -> 1.0311445 | I16: =C16*G16 -> 4646.8008 | J16: =D16*H16 -> 4575.1882 | K16: =D16+B16*$D$4*(1-1/H16) -> 4630.2188 | L16: =CHOOSE($D$5,I16,J16,K16) -> 4575.1882 | M16: =L16-D16 -> 138.18825 | N16: =L16-C16 -> 894.18825 | O16: =IF(B16=0,0,L16/B16) -> 0.44341813 | P16: =L16-Triangle_Data!L15 -> -97.811751
A17: =Triangle_Data!A16 -> 2022 | B17: =INDEX(LR_Model!$D$6:$D$17,MATCH(A17,LR_Model!$A$6:$A$17,0)) -> 11437 | C17: =Triangle_Data!B16 -> 2939 | D17: =Triangle_Data!B29 -> 4813 | E17: =D17-C17 -> 1874 | F17: 12 | G17: =Chain_Ladder!B26 -> 1.9389376 | H17: =Chain_Ladder!B47 -> 1.2172646 | I17: =C17*G17 -> 5698.5377 | J17: =D17*H17 -> 5858.6947 | K17: =D17+B17*$D$4*(1-1/H17) -> 6078.6332 | L17: =CHOOSE($D$5,I17,J17,K17) -> 5858.6947 | M17: =L17-D17 -> 1045.6947 | N17: =L17-C17 -> 2919.6947 | O17: =IF(B17=0,0,L17/B17) -> 0.512258 | P17: =L17-Triangle_Data!L16 -> 142.69469
A18: Total | B18: =SUM(B8:B17) -> 78660 | C18: =SUM(C8:C17) -> 43943 | D18: =SUM(D8:D17) -> 47591 | E18: =SUM(E8:E17) -> 3648 | I18: =SUM(I8:I17) -> 48663.457 | J18: =SUM(J8:J17) -> 48878.044 | K18: =SUM(K8:K17) -> 49148.977 | L18: =SUM(L8:L17) -> 48878.044 | M18: =SUM(M8:M17) -> 1287.0442 | N18: =SUM(N8:N17) -> 4935.0442 | O18: =IF(B18=0,0,L18/B18) -> 0.62138373 | P18: =SUM(P8:P17) -> 253.04419
A20: Method comparison (all accident years)
A21: Method | D21: Ultimate | E21: IBNR | F21: Ultimate LR
A22: Paid chain-ladder | D22: =I18 -> 48663.457 | E22: =D22-D18 -> 1072.4566 | F22: =IF(B18=0,0,D22/B18) -> 0.61865569
A23: Reported chain-ladder | D23: =J18 -> 48878.044 | E23: =D23-D18 -> 1287.0442 | F23: =IF(B18=0,0,D23/B18) -> 0.62138373
A24: Bornhuetter-Ferguson | D24: =K18 -> 49148.977 | E24: =D24-D18 -> 1557.9774 | F24: =IF(B18=0,0,D24/B18) -> 0.62482809
A25: Simulated true ultimate | D25: =SUM(Triangle_Data!L7:L16) -> 48625 | E25: =D25-D18 -> 1034 | F25: =IF(B18=0,0,D25/B18) -> 0.61816679
A27: IBNR = selected ultimate - reported to date. Total unpaid = selected ultimate - paid to date (case reserves + IBNR). BF ultimate = reported + EP x ELR x (1 - 1/CDF).

Sheet Queries
B3: 1) What is the earning fraction, and why does it matter?
B5: An annual policy's premium is written on the day the policy is sold. It is earned gradually, as each day of coverage passes. On any reporting date, the part not yet earned sits on the balance sheet as the unearned premium reserve.
B7: The earning fraction is the share of a year's written premium that gets earned in that same year. The model uses it to estimate earned premium:
B9: Earned(t) = f × Written(t) + (1 − f) × Written(t−1)
B11: It matters because a loss ratio should compare claims from a period with the premium for the coverage given in that same period. Earned premium is that premium; written premium isn't. IBC publishes only written premium, so the model has to estimate earned.
B13: 2) Why 50%? Is it set by a regulator?
B15: No, it's an actuarial approximation, not a rule. The logic: if annual policies are sold evenly through the year, the average policy starts mid-year. By 31 December it has used 6 of its 12 months, so about 50% of the year's sales are earned that year and the other 50% the next year.
B17: What regulators and accounting standards do require (OSFI, IFRS 17) is that premium be recognized over the coverage period. Insurers calculate that exactly, policy by policy, usually day by day. We use 50% only because we don't have policy-level data.
B19: You'd change the fraction when the assumption doesn't hold:
B21: Lots of 1 January renewals: more premium is earned in the year it's written, so the fraction goes up.
B22: Sales concentrated late in the year: the fraction goes down.
B23: Policies longer or shorter than 12 months: a different pattern altogether.
... B59: At the moment the status has two values: "Above target" when the ratio is over 65%, and "Within target" otherwise. You want "Within target" most years, but not far below target.
D60: incurred loss/earned premium
B61: In this data, 5 of 12 years are above target: 2011, 2012, 2013, 2016 and 2018. 2012 only just misses, at 65.5%. The catastrophe-heavy years are 2013 (Alberta and Toronto floods) and 2016 (Fort McMurray wildfire). The 2021–2022 results sit well under target because insurers raised rates sharply then.
B63: A better status would have three bands: "Well below", "Within ± tolerance" and "Above". That catches both underpricing and overpricing.
B65: 7) How do insurers reach the target in practice?
B67: The levers, roughly in order of how fast they work:
B69: Pricing: rate increases, and refining rating factors and individual risk rating. Because of the earning fraction, a rate increase takes about two years to fully flow into earned premium.
B70: Underwriting selection: judging risks by construction, occupancy, fire protection and exposure, inspecting before binding, and leaving unprofitable segments.
B71: Terms and conditions: higher deductibles (especially for catastrophe perils), sublimits, coinsurance clauses and exclusions.
B72: Insurance-to-value: making sure buildings are insured for their real replacement cost. Underinsured buildings collect too little premium for the risk.
B73: Risk control: sprinklers, maintenance programs and loss-prevention surveys.
B74: Reinsurance: catastrophe excess-of-loss cover reduces net losses and volatility, at the cost of reinsurance premium.
B75: Claims management: recovering costs from at-fault parties, salvage, fraud detection and managed repair networks.
B76: Portfolio mix: spreading geographic concentrations so one flood or wildfire can't wreck the year.
... B91: Read it alongside the multi-year averages so one catastrophe year isn't mistaken for a trend.
